Workbook

Sheet About
A1: Project 03 — Budget vs Actual Variance Analysis (FY2025)
A2: Portfolio project using FICTIONAL data for a fictional company (Northwind Field Services LLC). Not real employment results.
A4: Purpose
A5: Compare FY2025 actual results with budget, explain material variances, and split revenue variance into price and volume effects.
A7: Sheets
A8: 1. Assumptions — fiscal year, materiality thresholds (yellow = editable).
A9: 2. Data — monthly budget and actual by account and department (inputs, blue).
A10: 3. Variance_Analysis — full-year budget vs actual by account: variance $, %, favourable/unfavourable, materiality flag and commentary.
A11: 4. Monthly_PnL — monthly budget vs actual operating profit.
A12: 5. Price_Volume — revenue variance split into volume and price effects by service line.
A13: 6. Dept_Variance — operating expense variance by department.
A14: 7. Dashboard — KPI tiles and charts.
... A22: Author: Muhammed Shabeeb MK — Finance & Accounting portfolio

Sheet Dashboard
A1: Budget vs Actual Dashboard — FY2025 (fictional data)
A3: Actual revenue ($) | B3: =Variance_Analysis!D9 -> 10523108 | D3: Revenue vs budget ($) | E3: =Variance_Analysis!E9 -> 235458
A5: Actual gross margin % | B5: =Variance_Analysis!D18 -> 0.49658409 | D5: Gross margin vs budget (pts) | E5: =Variance_Analysis!E18 -> -0.043388597
A7: Actual operating profit ($) | B7: =Variance_Analysis!D33 -> 2445608 | D7: Operating profit vs budget ($) | E7: =Variance_Analysis!E33 -> -421442
A9: Opex vs budget ($) | B9: =Variance_Analysis!E31 -> 92000 | D9: Material variances (count) | E9: =COUNTIF(Variance_Analysis!H5:H34,"Yes") -> 7

Sheet Assumptions
A1: Assumption | B1: Value | C1: Note
A2: Fiscal year | B2: FY2025 | C2: Jan–Dec 2025
A3: Materiality threshold – absolute ($) | B3: 25000 | C3: Variance must exceed this amount…
A4: Materiality threshold – percentage | B4: 0.05 | C4: …AND this % of budget to be flagged material
A5: Currency | B5: USD | C5: Fictional amounts

Sheet Data
A1: Month | B1: Account | C1: Category | D1: Department | E1: Budget Units | F1: Budget Price ($) | G1: Actual Units | H1: Actual Price ($) | I1: Budget ($) | J1: Actual ($)
A2: 45658 | B2: Traffic Management Services | C2: Revenue | D2: Operations | E2: 357 | F2: 1150 | G2: 385 | H2: 1124 | I2: =E2*F2 -> 410550 | J2: =G2*H2 -> 432740
A3: 45658 | B3: Equipment Rental | C3: Revenue | D3: Operations | E3: 221 | F3: 680 | G3: 212 | H3: 717 | I3: =E3*F3 -> 150280 | J3: =G3*H3 -> 152004
A4: 45658 | B4: Maintenance Contracts | C4: Revenue | D4: Operations | E4: 32 | F4: 5200 | G4: 34 | H4: 5319 | I4: =E4*F4 -> 166400 | J4: =G4*H4 -> 180846
A5: 45658 | B5: Direct Labour | C5: COGS | D5: Operations | I5: 218200 | J5: 232100
A6: 45658 | B6: Materials & Consumables | C6: COGS | D6: Operations | I6: 65500 | J6: 77000
A7: 45658 | B7: Subcontractors | C7: COGS | D7: Operations | I7: 50900 | J7: 69400
A8: 45658 | B8: Admin Salaries | C8: Opex | D8: Finance & Admin | I8: 62000 | J8: 64600
A9: 45658 | B9: Sales Salaries & Commission | C9: Opex | D9: Sales & Marketing | I9: 38000 | J9: 41700
A10: 45658 | B10: Marketing | C10: Opex | D10: Sales & Marketing | I10: 14000 | J10: 10300
A11: 45658 | B11: Office Rent | C11: Opex | D11: Finance & Admin | I11: 22000 | J11: 22000
A12: 45658 | B12: Utilities | C12: Opex | D12: Finance & Admin | I12: 5500 | J12: 6000
A13: 45658 | B13: IT & Software | C13: Opex | D13: IT | I13: 12000 | J13: 13700
A14: 45658 | B14: Travel | C14: Opex | D14: Sales & Marketing | I14: 6500 | J14: 5600
A15: 45658 | B15: Professional Fees | C15: Opex | D15: Finance & Admin | I15: 8000 | J15: 10900
A16: 45658 | B16: Vehicle Fuel & Maintenance | C16: Opex | D16: Operations | I16: 26000 | J16: 26900
A17: 45658 | B17: Depreciation | C17: Opex | D17: Finance & Admin | I17: 30000 | J17: 30000
A18: 45689 | B18: Traffic Management Services | C18: Revenue | D18: Operations | E18: 370 | F18: 1150 | G18: 377 | H18: 1108 | I18: =E18*F18 -> 425500 | J18: =G18*H18 -> 417716
A19: 45689 | B19: Equipment Rental | C19: Revenue | D19: Operations | E19: 229 | F19: 680 | G19: 223 | H19: 713 | I19: =E19*F19 -> 155720 | J19: =G19*H19 -> 158999
A20: 45689 | B20: Maintenance Contracts | C20: Revenue | D20: Operations | E20: 33 | F20: 5200 | G20: 32 | H20: 5299 | I20: =E20*F20 -> 171600 | J20: =G20*H20 -> 169568
A21: 45689 | B21: Direct Labour | C21: COGS | D21: Operations | I21: 225800 | J21: 228300
A22: 45689 | B22: Materials & Consumables | C22: COGS | D22: Operations | I22: 67800 | J22: 75900
A23: 45689 | B23: Subcontractors | C23: COGS | D23: Operations | I23: 52700 | J23: 63300
A24: 45689 | B24: Admin Salaries | C24: Opex | D24: Finance & Admin | I24: 62000 | J24: 58800
A25: 45689 | B25: Sales Salaries & Commission | C25: Opex | D25: Sales & Marketing | I25: 38000 | J25: 41600
A26: 45689 | B26: Marketing | C26: Opex | D26: Sales & Marketing | I26: 14000 | J26: 10500
A27: 45689 | B27: Office Rent | C27: Opex | D27: Finance & Admin | I27: 22000 | J27: 22000
A28: 45689 | B28: Utilities | C28: Opex | D28: Finance & Admin | I28: 5500 | J28: 5800
A29: 45689 | B29: IT & Software | C29: Opex | D29: IT | I29: 12000 | J29: 15100
A30: 45689 | B30: Travel | C30: Opex | D30: Sales & Marketing | I30: 6500 | J30: 5800
A31: 45689 | B31: Professional Fees | C31: Opex | D31: Finance & Admin | I31: 8000 | J31: 10500
A32: 45689 | B32: Vehicle Fuel & Maintenance | C32: Opex | D32: Operations | I32: 26000 | J32: 30700
A33: 45689 | B33: Depreciation | C33: Opex | D33: Finance & Admin | I33: 30000 | J33: 30000
A34: 45717 | B34: Traffic Management Services | C34: Revenue | D34: Operations | E34: 407 | F34: 1150 | G34: 434 | H34: 1121 | I34: =E34*F34 -> 468050 | J34: =G34*H34 -> 486514
A35: 45717 | B35: Equipment Rental | C35: Revenue | D35: Operations | E35: 252 | F35: 680 | G35: 222 | H35: 717 | I35: =E35*F35 -> 171360 | J35: =G35*H35 -> 159174
A36: 45717 | B36: Maintenance Contracts | C36: Revenue | D36: Operations | E36: 37 | F36: 5200 | G36: 39 | H36: 5326 | I36: =E36*F36 -> 192400 | J36: =G36*H36 -> 207714
A37: 45717 | B37: Direct Labour | C37: COGS | D37: Operations | I37: 249500 | J37: 277300
A38: 45717 | B38: Materials & Consumables | C38: COGS | D38: Operations | I38: 74900 | J38: 84600
A39: 45717 | B39: Subcontractors | C39: COGS | D39: Operations | I39: 58200 | J39: 73800
A40: 45717 | B40: Admin Salaries | C40: Opex | D40: Finance & Admin | I40: 62000 | J40: 60300
...

Sheet Variance_Analysis
A1: FY2025 Budget vs Actual — by account
A2: Variance = Actual − Budget · F = favourable · U = unfavourable · Material = beyond both thresholds in Assumptions
A4: Account | B4: Category | C4: Budget ($) | D4: Actual ($) | E4: Variance ($) | F4: Var % | G4: F/U | H4: Material? | I4: Commentary (analyst explanation)
A5: Revenue
A6: Traffic Management Services | B6: Revenue | C6: =SUMIFS(Data!$I$2:$I$193,Data!$B$2:$B$193,$A6) -> 5794850 | D6: =SUMIFS(Data!$J$2:$J$193,Data!$B$2:$B$193,$A6) -> 5942980 | E6: =D6-C6 -> 148130 | F6: =IF(C6=0,0,E6/C6) -> 0.025562353 | G6: =IF(E6=0,"-",IF(B6="Revenue",IF(E6>0,"F","U"),IF(E6<0,"F","U"))) -> F | H6: =IF(AND(ABS(E6)>=Assumptions!$B$3,ABS(F6)>=Assumptions!$B$4),"Yes","No") -> No | I6: Volumes above plan from new highway-maintenance contracts; slight price discounting to win work.
A7: Equipment Rental | B7: Revenue | C7: =SUMIFS(Data!$I$2:$I$193,Data!$B$2:$B$193,$A7) -> 2121600 | D7: =SUMIFS(Data!$J$2:$J$193,Data!$B$2:$B$193,$A7) -> 2059395 | E7: =D7-C7 -> -62205 | F7: =IF(C7=0,0,E7/C7) -> -0.029319853 | G7: =IF(E7=0,"-",IF(B7="Revenue",IF(E7>0,"F","U"),IF(E7<0,"F","U"))) -> U | H7: =IF(AND(ABS(E7)>=Assumptions!$B$3,ABS(F7)>=Assumptions!$B$4),"Yes","No") -> No | I7: Fewer rental days than budget, partly offset by a price increase effective Q1.
A8: Maintenance Contracts | B8: Revenue | C8: =SUMIFS(Data!$I$2:$I$193,Data!$B$2:$B$193,$A8) -> 2371200 | D8: =SUMIFS(Data!$J$2:$J$193,Data!$B$2:$B$193,$A8) -> 2520733 | E8: =D8-C8 -> 149533 | F8: =IF(C8=0,0,E8/C8) -> 0.063062163 | G8: =IF(E8=0,"-",IF(B8="Revenue",IF(E8>0,"F","U"),IF(E8<0,"F","U"))) -> F | H8: =IF(AND(ABS(E8)>=Assumptions!$B$3,ABS(F8)>=Assumptions!$B$4),"Yes","No") -> Yes | I8: Higher contract count than plan (volume) plus a small price uplift on renewals.
A9: Total Revenue | B9: Revenue | C9: =SUM(C6:C8) -> 10287650 | D9: =SUM(D6:D8) -> 10523108 | E9: =SUM(E6:E8) -> 235458 | F9: =IF(C9=0,0,E9/C9) -> 0.022887443 | G9: =IF(E9=0,"-",IF(B9="Revenue",IF(E9>0,"F","U"),IF(E9<0,"F","U"))) -> F
A11: Cost of Services
A12: Direct Labour | B12: COGS | C12: =SUMIFS(Data!$I$2:$I$193,Data!$B$2:$B$193,$A12) -> 3086200 | D12: =SUMIFS(Data!$J$2:$J$193,Data!$B$2:$B$193,$A12) -> 3314100 | E12: =D12-C12 -> 227900 | F12: =IF(C12=0,0,E12/C12) -> 0.073844858 | G12: =IF(E12=0,"-",IF(B12="Revenue",IF(E12>0,"F","U"),IF(E12<0,"F","U"))) -> U | H12: =IF(AND(ABS(E12)>=Assumptions!$B$3,ABS(F12)>=Assumptions!$B$4),"Yes","No") -> Yes | I12: Overtime to cover higher service volumes and wage inflation above the budgeted rate.
A13: Materials & Consumables | B13: COGS | C13: =SUMIFS(Data!$I$2:$I$193,Data!$B$2:$B$193,$A13) -> 926300 | D13: =SUMIFS(Data!$J$2:$J$193,Data!$B$2:$B$193,$A13) -> 1070000 | E13: =D13-C13 -> 143700 | F13: =IF(C13=0,0,E13/C13) -> 0.15513333 | G13: =IF(E13=0,"-",IF(B13="Revenue",IF(E13>0,"F","U"),IF(E13<0,"F","U"))) -> U | H13: =IF(AND(ABS(E13)>=Assumptions!$B$3,ABS(F13)>=Assumptions!$B$4),"Yes","No") -> Yes | I13: Supplier price increases on cones, barriers and signage consumables.
A14: Subcontractors | B14: COGS | C14: =SUMIFS(Data!$I$2:$I$193,Data!$B$2:$B$193,$A14) -> 720100 | D14: =SUMIFS(Data!$J$2:$J$193,Data!$B$2:$B$193,$A14) -> 913400 | E14: =D14-C14 -> 193300 | F14: =IF(C14=0,0,E14/C14) -> 0.26843494 | G14: =IF(E14=0,"-",IF(B14="Revenue",IF(E14>0,"F","U"),IF(E14<0,"F","U"))) -> U | H14: =IF(AND(ABS(E14)>=Assumptions!$B$3,ABS(F14)>=Assumptions!$B$4),"Yes","No") -> Yes | I14: Peak-season capacity outsourced; review make-vs-buy for recurring peaks.
A15: Total Cost of Services | B15: COGS | C15: =SUM(C12:C14) -> 4732600 | D15: =SUM(D12:D14) -> 5297500 | E15: =SUM(E12:E14) -> 564900 | F15: =IF(C15=0,0,E15/C15) -> 0.11936356 | G15: =IF(E15=0,"-",IF(B15="Revenue",IF(E15>0,"F","U"),IF(E15<0,"F","U"))) -> U
A17: Gross Profit | C17: =C9-C15 -> 5555050 | D17: =D9-D15 -> 5225608 | E17: =E9-E15 -> -329442 | F17: =IF(C17=0,0,E17/C17) -> -0.059304957 | G17: =IF(E17=0,"-",IF(E17>0,"F","U")) -> U
A18: Gross margin % | C18: =IF(C9=0,0,C17/C9) -> 0.53997269 | D18: =IF(D9=0,0,D17/D9) -> 0.49658409 | E18: =D18-C18 -> -0.043388597
A20: Operating Expenses
A21: Admin Salaries | B21: Opex | C21: =SUMIFS(Data!$I$2:$I$193,Data!$B$2:$B$193,$A21) -> 744000 | D21: =SUMIFS(Data!$J$2:$J$193,Data!$B$2:$B$193,$A21) -> 750100 | E21: =D21-C21 -> 6100 | F21: =IF(C21=0,0,E21/C21) -> 0.0081989247 | G21: =IF(E21=0,"-",IF(B21="Revenue",IF(E21>0,"F","U"),IF(E21<0,"F","U"))) -> U | H21: =IF(AND(ABS(E21)>=Assumptions!$B$3,ABS(F21)>=Assumptions!$B$4),"Yes","No") -> No | I21: Annual increments slightly above budget.
A22: Sales Salaries & Commission | B22: Opex | C22: =SUMIFS(Data!$I$2:$I$193,Data!$B$2:$B$193,$A22) -> 456000 | D22: =SUMIFS(Data!$J$2:$J$193,Data!$B$2:$B$193,$A22) -> 476300 | E22: =D22-C22 -> 20300 | F22: =IF(C22=0,0,E22/C22) -> 0.044517544 | G22: =IF(E22=0,"-",IF(B22="Revenue",IF(E22>0,"F","U"),IF(E22<0,"F","U"))) -> U | H22: =IF(AND(ABS(E22)>=Assumptions!$B$3,ABS(F22)>=Assumptions!$B$4),"Yes","No") -> No | I22: Higher commission on above-plan service revenue.
A23: Marketing | B23: Opex | C23: =SUMIFS(Data!$I$2:$I$193,Data!$B$2:$B$193,$A23) -> 168000 | D23: =SUMIFS(Data!$J$2:$J$193,Data!$B$2:$B$193,$A23) -> 146300 | E23: =D23-C23 -> -21700 | F23: =IF(C23=0,0,E23/C23) -> -0.12916667 | G23: =IF(E23=0,"-",IF(B23="Revenue",IF(E23>0,"F","U"),IF(E23<0,"F","U"))) -> F | H23: =IF(AND(ABS(E23)>=Assumptions!$B$3,ABS(F23)>=Assumptions!$B$4),"Yes","No") -> No | I23: Campaign spend deferred most of the year, partly offset by Oct–Nov trade-show costs.
A24: Office Rent | B24: Opex | C24: =SUMIFS(Data!$I$2:$I$193,Data!$B$2:$B$193,$A24) -> 264000 | D24: =SUMIFS(Data!$J$2:$J$193,Data!$B$2:$B$193,$A24) -> 264000 | E24: =D24-C24 -> 0 | F24: =IF(C24=0,0,E24/C24) -> 0 | G24: =IF(E24=0,"-",IF(B24="Revenue",IF(E24>0,"F","U"),IF(E24<0,"F","U"))) -> - | H24: =IF(AND(ABS(E24)>=Assumptions!$B$3,ABS(F24)>=Assumptions!$B$4),"Yes","No") -> No | I24: Fixed lease — on budget.
A25: Utilities | B25: Opex | C25: =SUMIFS(Data!$I$2:$I$193,Data!$B$2:$B$193,$A25) -> 66000 | D25: =SUMIFS(Data!$J$2:$J$193,Data!$B$2:$B$193,$A25) -> 73300 | E25: =D25-C25 -> 7300 | F25: =IF(C25=0,0,E25/C25) -> 0.11060606 | G25: =IF(E25=0,"-",IF(B25="Revenue",IF(E25>0,"F","U"),IF(E25<0,"F","U"))) -> U | H25: =IF(AND(ABS(E25)>=Assumptions!$B$3,ABS(F25)>=Assumptions!$B$4),"Yes","No") -> No | I25: Tariff increase from Q2.
A26: IT & Software | B26: Opex | C26: =SUMIFS(Data!$I$2:$I$193,Data!$B$2:$B$193,$A26) -> 144000 | D26: =SUMIFS(Data!$J$2:$J$193,Data!$B$2:$B$193,$A26) -> 171500 | E26: =D26-C26 -> 27500 | F26: =IF(C26=0,0,E26/C26) -> 0.19097222 | G26: =IF(E26=0,"-",IF(B26="Revenue",IF(E26>0,"F","U"),IF(E26<0,"F","U"))) -> U | H26: =IF(AND(ABS(E26)>=Assumptions!$B$3,ABS(F26)>=Assumptions!$B$4),"Yes","No") -> Yes | I26: New fleet-tracking and ERP licences not in original budget.
A27: Travel | B27: Opex | C27: =SUMIFS(Data!$I$2:$I$193,Data!$B$2:$B$193,$A27) -> 78000 | D27: =SUMIFS(Data!$J$2:$J$193,Data!$B$2:$B$193,$A27) -> 66000 | E27: =D27-C27 -> -12000 | F27: =IF(C27=0,0,E27/C27) -> -0.15384615 | G27: =IF(E27=0,"-",IF(B27="Revenue",IF(E27>0,"F","U"),IF(E27<0,"F","U"))) -> F | H27: =IF(AND(ABS(E27)>=Assumptions!$B$3,ABS(F27)>=Assumptions!$B$4),"Yes","No") -> No | I27: Shift to virtual client meetings.
A28: Professional Fees | B28: Opex | C28: =SUMIFS(Data!$I$2:$I$193,Data!$B$2:$B$193,$A28) -> 96000 | D28: =SUMIFS(Data!$J$2:$J$193,Data!$B$2:$B$193,$A28) -> 131200 | E28: =D28-C28 -> 35200 | F28: =IF(C28=0,0,E28/C28) -> 0.36666667 | G28: =IF(E28=0,"-",IF(B28="Revenue",IF(E28>0,"F","U"),IF(E28<0,"F","U"))) -> U | H28: =IF(AND(ABS(E28)>=Assumptions!$B$3,ABS(F28)>=Assumptions!$B$4),"Yes","No") -> Yes | I28: Additional advisory fees for Corporate Tax registration and audit.
A29: Vehicle Fuel & Maintenance | B29: Opex | C29: =SUMIFS(Data!$I$2:$I$193,Data!$B$2:$B$193,$A29) -> 312000 | D29: =SUMIFS(Data!$J$2:$J$193,Data!$B$2:$B$193,$A29) -> 341300 | E29: =D29-C29 -> 29300 | F29: =IF(C29=0,0,E29/C29) -> 0.093910256 | G29: =IF(E29=0,"-",IF(B29="Revenue",IF(E29>0,"F","U"),IF(E29<0,"F","U"))) -> U | H29: =IF(AND(ABS(E29)>=Assumptions!$B$3,ABS(F29)>=Assumptions!$B$4),"Yes","No") -> Yes | I29: Higher fuel prices and more site deployments.
A30: Depreciation | B30: Opex | C30: =SUMIFS(Data!$I$2:$I$193,Data!$B$2:$B$193,$A30) -> 360000 | D30: =SUMIFS(Data!$J$2:$J$193,Data!$B$2:$B$193,$A30) -> 360000 | E30: =D30-C30 -> 0 | F30: =IF(C30=0,0,E30/C30) -> 0 | G30: =IF(E30=0,"-",IF(B30="Revenue",IF(E30>0,"F","U"),IF(E30<0,"F","U"))) -> - | H30: =IF(AND(ABS(E30)>=Assumptions!$B$3,ABS(F30)>=Assumptions!$B$4),"Yes","No") -> No | I30: Asset base unchanged — on budget.
A31: Total Operating Expenses | B31: Opex | C31: =SUM(C21:C30) -> 2688000 | D31: =SUM(D21:D30) -> 2780000 | E31: =SUM(E21:E30) -> 92000 | F31: =IF(C31=0,0,E31/C31) -> 0.03422619 | G31: =IF(E31=0,"-",IF(B31="Revenue",IF(E31>0,"F","U"),IF(E31<0,"F","U"))) -> U
A33: Operating Profit (EBIT) | C33: =C17-C31 -> 2867050 | D33: =D17-D31 -> 2445608 | E33: =E17-E31 -> -421442 | F33: =IF(C33=0,0,E33/C33) -> -0.14699499 | G33: =IF(E33=0,"-",IF(E33>0,"F","U")) -> U
A34: Operating margin % | C34: =IF(C9=0,0,C33/C9) -> 0.27868852 | D34: =IF(D9=0,0,D33/D9) -> 0.23240358 | E34: =D34-C34 -> -0.046284942

Sheet Monthly_PnL
A1: Monthly Budget vs Actual — Revenue and Operating Profit
A3: Month | B3: Budget Revenue | C3: Actual Revenue | D3: Budget Costs | E3: Actual Costs | F3: Budget EBIT | G3: Actual EBIT | H3: EBIT Variance | I3: Cum. EBIT Var. | J3: EBIT Var %
A4: 45658 | B4: =SUMIFS(Data!$I$2:$I$193,Data!$A$2:$A$193,$A4,Data!$C$2:$C$193,"Revenue") -> 727230 | C4: =SUMIFS(Data!$J$2:$J$193,Data!$A$2:$A$193,$A4,Data!$C$2:$C$193,"Revenue") -> 765590 | D4: =SUMIFS(Data!$I$2:$I$193,Data!$A$2:$A$193,$A4,Data!$C$2:$C$193,"<>Revenue") -> 558600 | E4: =SUMIFS(Data!$J$2:$J$193,Data!$A$2:$A$193,$A4,Data!$C$2:$C$193,"<>Revenue") -> 610200 | F4: =B4-D4 -> 168630 | G4: =C4-E4 -> 155390 | H4: =G4-F4 -> -13240 | I4: =H4 -> -13240 | J4: =IF(F4=0,0,H4/F4) -> -0.078515092
A5: 45689 | B5: =SUMIFS(Data!$I$2:$I$193,Data!$A$2:$A$193,$A5,Data!$C$2:$C$193,"Revenue") -> 752820 | C5: =SUMIFS(Data!$J$2:$J$193,Data!$A$2:$A$193,$A5,Data!$C$2:$C$193,"Revenue") -> 746283 | D5: =SUMIFS(Data!$I$2:$I$193,Data!$A$2:$A$193,$A5,Data!$C$2:$C$193,"<>Revenue") -> 570300 | E5: =SUMIFS(Data!$J$2:$J$193,Data!$A$2:$A$193,$A5,Data!$C$2:$C$193,"<>Revenue") -> 598300 | F5: =B5-D5 -> 182520 | G5: =C5-E5 -> 147983 | H5: =G5-F5 -> -34537 | I5: =I4+H5 -> -47777 | J5: =IF(F5=0,0,H5/F5) -> -0.1892231
A6: 45717 | B6: =SUMIFS(Data!$I$2:$I$193,Data!$A$2:$A$193,$A6,Data!$C$2:$C$193,"Revenue") -> 831810 | C6: =SUMIFS(Data!$J$2:$J$193,Data!$A$2:$A$193,$A6,Data!$C$2:$C$193,"Revenue") -> 853402 | D6: =SUMIFS(Data!$I$2:$I$193,Data!$A$2:$A$193,$A6,Data!$C$2:$C$193,"<>Revenue") -> 606600 | E6: =SUMIFS(Data!$J$2:$J$193,Data!$A$2:$A$193,$A6,Data!$C$2:$C$193,"<>Revenue") -> 660500 | F6: =B6-D6 -> 225210 | G6: =C6-E6 -> 192902 | H6: =G6-F6 -> -32308 | I6: =I5+H6 -> -80085 | J6: =IF(F6=0,0,H6/F6) -> -0.14345722
A7: 45748 | B7: =SUMIFS(Data!$I$2:$I$193,Data!$A$2:$A$193,$A7,Data!$C$2:$C$193,"Revenue") -> 857400 | C7: =SUMIFS(Data!$J$2:$J$193,Data!$A$2:$A$193,$A7,Data!$C$2:$C$193,"Revenue") -> 861651 | D7: =SUMIFS(Data!$I$2:$I$193,Data!$A$2:$A$193,$A7,Data!$C$2:$C$193,"<>Revenue") -> 618400 | E7: =SUMIFS(Data!$J$2:$J$193,Data!$A$2:$A$193,$A7,Data!$C$2:$C$193,"<>Revenue") -> 656400 | F7: =B7-D7 -> 239000 | G7: =C7-E7 -> 205251 | H7: =G7-F7 -> -33749 | I7: =I6+H7 -> -113834 | J7: =IF(F7=0,0,H7/F7) -> -0.14120921
A8: 45778 | B8: =SUMIFS(Data!$I$2:$I$193,Data!$A$2:$A$193,$A8,Data!$C$2:$C$193,"Revenue") -> 900790 | C8: =SUMIFS(Data!$J$2:$J$193,Data!$A$2:$A$193,$A8,Data!$C$2:$C$193,"Revenue") -> 910845 | D8: =SUMIFS(Data!$I$2:$I$193,Data!$A$2:$A$193,$A8,Data!$C$2:$C$193,"<>Revenue") -> 638400 | E8: =SUMIFS(Data!$J$2:$J$193,Data!$A$2:$A$193,$A8,Data!$C$2:$C$193,"<>Revenue") -> 685300 | F8: =B8-D8 -> 262390 | G8: =C8-E8 -> 225545 | H8: =G8-F8 -> -36845 | I8: =I7+H8 -> -150679 | J8: =IF(F8=0,0,H8/F8) -> -0.14042075
A9: 45809 | B9: =SUMIFS(Data!$I$2:$I$193,Data!$A$2:$A$193,$A9,Data!$C$2:$C$193,"Revenue") -> 926380 | C9: =SUMIFS(Data!$J$2:$J$193,Data!$A$2:$A$193,$A9,Data!$C$2:$C$193,"Revenue") -> 956600 | D9: =SUMIFS(Data!$I$2:$I$193,Data!$A$2:$A$193,$A9,Data!$C$2:$C$193,"<>Revenue") -> 650100 | E9: =SUMIFS(Data!$J$2:$J$193,Data!$A$2:$A$193,$A9,Data!$C$2:$C$193,"<>Revenue") -> 699200 | F9: =B9-D9 -> 276280 | G9: =C9-E9 -> 257400 | H9: =G9-F9 -> -18880 | I9: =I8+H9 -> -169559 | J9: =IF(F9=0,0,H9/F9) -> -0.06833647
A10: 45839 | B10: =SUMIFS(Data!$I$2:$I$193,Data!$A$2:$A$193,$A10,Data!$C$2:$C$193,"Revenue") -> 814010 | C10: =SUMIFS(Data!$J$2:$J$193,Data!$A$2:$A$193,$A10,Data!$C$2:$C$193,"Revenue") -> 819719 | D10: =SUMIFS(Data!$I$2:$I$193,Data!$A$2:$A$193,$A10,Data!$C$2:$C$193,"<>Revenue") -> 598500 | E10: =SUMIFS(Data!$J$2:$J$193,Data!$A$2:$A$193,$A10,Data!$C$2:$C$193,"<>Revenue") -> 635800 | F10: =B10-D10 -> 215510 | G10: =C10-E10 -> 183919 | H10: =G10-F10 -> -31591 | I10: =I9+H10 -> -201150 | J10: =IF(F10=0,0,H10/F10) -> -0.14658717
A11: 45870 | B11: =SUMIFS(Data!$I$2:$I$193,Data!$A$2:$A$193,$A11,Data!$C$2:$C$193,"Revenue") -> 788420 | C11: =SUMIFS(Data!$J$2:$J$193,Data!$A$2:$A$193,$A11,Data!$C$2:$C$193,"Revenue") -> 800726 | D11: =SUMIFS(Data!$I$2:$I$193,Data!$A$2:$A$193,$A11,Data!$C$2:$C$193,"<>Revenue") -> 586700 | E11: =SUMIFS(Data!$J$2:$J$193,Data!$A$2:$A$193,$A11,Data!$C$2:$C$193,"<>Revenue") -> 646200 | F11: =B11-D11 -> 201720 | G11: =C11-E11 -> 154526 | H11: =G11-F11 -> -47194 | I11: =I10+H11 -> -248344 | J11: =IF(F11=0,0,H11/F11) -> -0.23395796
A12: 45901 | B12: =SUMIFS(Data!$I$2:$I$193,Data!$A$2:$A$193,$A12,Data!$C$2:$C$193,"Revenue") -> 907430 | C12: =SUMIFS(Data!$J$2:$J$193,Data!$A$2:$A$193,$A12,Data!$C$2:$C$193,"Revenue") -> 944480 | D12: =SUMIFS(Data!$I$2:$I$193,Data!$A$2:$A$193,$A12,Data!$C$2:$C$193,"<>Revenue") -> 641400 | E12: =SUMIFS(Data!$J$2:$J$193,Data!$A$2:$A$193,$A12,Data!$C$2:$C$193,"<>Revenue") -> 719200 | F12: =B12-D12 -> 266030 | G12: =C12-E12 -> 225280 | H12: =G12-F12 -> -40750 | I12: =I11+H12 -> -289094 | J12: =IF(F12=0,0,H12/F12) -> -0.15317821
A13: 45931 | B13: =SUMIFS(Data!$I$2:$I$193,Data!$A$2:$A$193,$A13,Data!$C$2:$C$193,"Revenue") -> 944180 | C13: =SUMIFS(Data!$J$2:$J$193,Data!$A$2:$A$193,$A13,Data!$C$2:$C$193,"Revenue") -> 982631 | D13: =SUMIFS(Data!$I$2:$I$193,Data!$A$2:$A$193,$A13,Data!$C$2:$C$193,"<>Revenue") -> 658400 | E13: =SUMIFS(Data!$J$2:$J$193,Data!$A$2:$A$193,$A13,Data!$C$2:$C$193,"<>Revenue") -> 732700 | F13: =B13-D13 -> 285780 | G13: =C13-E13 -> 249931 | H13: =G13-F13 -> -35849 | I13: =I12+H13 -> -324943 | J13: =IF(F13=0,0,H13/F13) -> -0.12544265
A14: 45962 | B14: =SUMIFS(Data!$I$2:$I$193,Data!$A$2:$A$193,$A14,Data!$C$2:$C$193,"Revenue") -> 918590 | C14: =SUMIFS(Data!$J$2:$J$193,Data!$A$2:$A$193,$A14,Data!$C$2:$C$193,"Revenue") -> 964900 | D14: =SUMIFS(Data!$I$2:$I$193,Data!$A$2:$A$193,$A14,Data!$C$2:$C$193,"<>Revenue") -> 646600 | E14: =SUMIFS(Data!$J$2:$J$193,Data!$A$2:$A$193,$A14,Data!$C$2:$C$193,"<>Revenue") -> 740800 | F14: =B14-D14 -> 271990 | G14: =C14-E14 -> 224100 | H14: =G14-F14 -> -47890 | I14: =I13+H14 -> -372833 | J14: =IF(F14=0,0,H14/F14) -> -0.17607265
A15: 45992 | B15: =SUMIFS(Data!$I$2:$I$193,Data!$A$2:$A$193,$A15,Data!$C$2:$C$193,"Revenue") -> 918590 | C15: =SUMIFS(Data!$J$2:$J$193,Data!$A$2:$A$193,$A15,Data!$C$2:$C$193,"Revenue") -> 916281 | D15: =SUMIFS(Data!$I$2:$I$193,Data!$A$2:$A$193,$A15,Data!$C$2:$C$193,"<>Revenue") -> 646600 | E15: =SUMIFS(Data!$J$2:$J$193,Data!$A$2:$A$193,$A15,Data!$C$2:$C$193,"<>Revenue") -> 692900 | F15: =B15-D15 -> 271990 | G15: =C15-E15 -> 223381 | H15: =G15-F15 -> -48609 | I15: =I14+H15 -> -421442 | J15: =IF(F15=0,0,H15/F15) -> -0.17871613
A16: FY Total | B16: =SUM(B4:B15) -> 10287650 | C16: =SUM(C4:C15) -> 10523108 | D16: =SUM(D4:D15) -> 7420600 | E16: =SUM(E4:E15) -> 8077500 | F16: =SUM(F4:F15) -> 2867050 | G16: =SUM(G4:G15) -> 2445608 | H16: =SUM(H4:H15) -> -421442 | J16: =IF(F16=0,0,H16/F16) -> -0.14699499
A18: Check vs Variance_Analysis EBIT variance (should be 0) | H18: =H16-Variance_Analysis!E33 -> 0

Sheet Price_Volume
A1: Revenue variance — Price vs Volume (FY2025)
A2: Volume variance = (Actual units − Budget units) × Budget avg price · Price variance = (Actual avg price − Budget avg price) × Actual units
A4: Service line | B4: Budget Units | C4: Actual Units | D4: Budget Avg Price | E4: Actual Avg Price | F4: Budget Rev ($) | G4: Actual Rev ($) | H4: Volume Var ($) | I4: Price Var ($) | J4: Check
A5: Traffic Management Services | B5: =SUMIFS(Data!$E$2:$E$193,Data!$B$2:$B$193,$A5) -> 5039 | C5: =SUMIFS(Data!$G$2:$G$193,Data!$B$2:$B$193,$A5) -> 5306 | D5: =IF(B5=0,0,F5/B5) -> 1150 | E5: =IF(C5=0,0,G5/C5) -> 1120.049 | F5: =SUMIFS(Data!$I$2:$I$193,Data!$B$2:$B$193,$A5) -> 5794850 | G5: =SUMIFS(Data!$J$2:$J$193,Data!$B$2:$B$193,$A5) -> 5942980 | H5: =(C5-B5)*D5 -> 307050 | I5: =(E5-D5)*C5 -> -158920 | J5: =ROUND(G5-F5-H5-I5,0) -> 0
A6: Equipment Rental | B6: =SUMIFS(Data!$E$2:$E$193,Data!$B$2:$B$193,$A6) -> 3120 | C6: =SUMIFS(Data!$G$2:$G$193,Data!$B$2:$B$193,$A6) -> 2903 | D6: =IF(B6=0,0,F6/B6) -> 680 | E6: =IF(C6=0,0,G6/C6) -> 709.40234 | F6: =SUMIFS(Data!$I$2:$I$193,Data!$B$2:$B$193,$A6) -> 2121600 | G6: =SUMIFS(Data!$J$2:$J$193,Data!$B$2:$B$193,$A6) -> 2059395 | H6: =(C6-B6)*D6 -> -147560 | I6: =(E6-D6)*C6 -> 85355 | J6: =ROUND(G6-F6-H6-I6,0) -> 0
A7: Maintenance Contracts | B7: =SUMIFS(Data!$E$2:$E$193,Data!$B$2:$B$193,$A7) -> 456 | C7: =SUMIFS(Data!$G$2:$G$193,Data!$B$2:$B$193,$A7) -> 477 | D7: =IF(B7=0,0,F7/B7) -> 5200 | E7: =IF(C7=0,0,G7/C7) -> 5284.5556 | F7: =SUMIFS(Data!$I$2:$I$193,Data!$B$2:$B$193,$A7) -> 2371200 | G7: =SUMIFS(Data!$J$2:$J$193,Data!$B$2:$B$193,$A7) -> 2520733 | H7: =(C7-B7)*D7 -> 109200 | I7: =(E7-D7)*C7 -> 40333 | J7: =ROUND(G7-F7-H7-I7,0) -> 0
A8: Total | F8: =SUM(F5:F7) -> 10287650 | G8: =SUM(G5:G7) -> 10523108 | H8: =SUM(H5:H7) -> 268690 | I8: =SUM(I5:I7) -> -33232

Sheet Dept_Variance
A1: Operating expenses by department (FY2025)
A3: Department | B3: Budget ($) | C3: Actual ($) | D3: Variance ($) | E3: Var % | F3: F/U
A4: Operations | B4: =SUMIFS(Data!$I$2:$I$193,Data!$D$2:$D$193,$A4,Data!$C$2:$C$193,"Opex") -> 312000 | C4: =SUMIFS(Data!$J$2:$J$193,Data!$D$2:$D$193,$A4,Data!$C$2:$C$193,"Opex") -> 341300 | D4: =C4-B4 -> 29300 | E4: =IF(B4=0,0,D4/B4) -> 0.093910256 | F4: =IF(D4=0,"-",IF(D4<0,"F","U")) -> U
A5: Sales & Marketing | B5: =SUMIFS(Data!$I$2:$I$193,Data!$D$2:$D$193,$A5,Data!$C$2:$C$193,"Opex") -> 702000 | C5: =SUMIFS(Data!$J$2:$J$193,Data!$D$2:$D$193,$A5,Data!$C$2:$C$193,"Opex") -> 688600 | D5: =C5-B5 -> -13400 | E5: =IF(B5=0,0,D5/B5) -> -0.019088319 | F5: =IF(D5=0,"-",IF(D5<0,"F","U")) -> F
A6: Finance & Admin | B6: =SUMIFS(Data!$I$2:$I$193,Data!$D$2:$D$193,$A6,Data!$C$2:$C$193,"Opex") -> 1530000 | C6: =SUMIFS(Data!$J$2:$J$193,Data!$D$2:$D$193,$A6,Data!$C$2:$C$193,"Opex") -> 1578600 | D6: =C6-B6 -> 48600 | E6: =IF(B6=0,0,D6/B6) -> 0.031764706 | F6: =IF(D6=0,"-",IF(D6<0,"F","U")) -> U
A7: IT | B7: =SUMIFS(Data!$I$2:$I$193,Data!$D$2:$D$193,$A7,Data!$C$2:$C$193,"Opex") -> 144000 | C7: =SUMIFS(Data!$J$2:$J$193,Data!$D$2:$D$193,$A7,Data!$C$2:$C$193,"Opex") -> 171500 | D7: =C7-B7 -> 27500 | E7: =IF(B7=0,0,D7/B7) -> 0.19097222 | F7: =IF(D7=0,"-",IF(D7<0,"F","U")) -> U
A8: Total Opex | B8: =SUM(B4:B7) -> 2688000 | C8: =SUM(C4:C7) -> 2780000 | D8: =SUM(D4:D7) -> 92000
A10: Check vs Variance_Analysis (should be 0) | D10: =D8-Variance_Analysis!E31 -> 0
